--------------------Moonraker Log Start--------------------
data_path: /home/sashi/TronXY_data
is_default_data_path: False
config_file: /home/sashi/TronXY_data/config/moonraker.conf
startup_warnings: []
verbose: False
debug: False
asyncio_debug: False
is_backup_config: False
log_file: /home/sashi/TronXY_data/logs/moonraker.log
software_version: v0.7.1-780-gdde9bcc
python_version: 3.9.2 (default, Feb 28 2021, 17:03:44)  [GCC 10.2.1 20210110]

#################### Moonraker Configuration ####################

[server]
host = 0.0.0.0
port = 7126
klippy_uds_address = /home/sashi/TronXY_data/comms/klippy.sock

[authorization]
trusted_clients = 
	10.0.0.0/8
	127.0.0.0/8
	169.254.0.0/16
	172.16.0.0/12
	192.168.0.0/16
	FE80::/10
	::1/128
cors_domains = 
	http://*.lan
	http://*.local
	https://my.mainsail.xyz
	http://my.mainsail.xyz
	https://app.fluidd.xyz
	http://app.fluidd.xyz

[octoprint_compat]

[history]

[update_manager]
channel = dev
refresh_interval = 168

[update_manager fluidd]
type = web
channel = stable
repo = fluidd-core/fluidd
path = ~/fluidd

#################################################################
All Configuration Files:
/home/sashi/TronXY_data/config/moonraker.conf
#################################################################
Unsafe Shutdown Count: 1

System Info:

***python***
  version: sys.version_info(major=3, minor=9, micro=2, releaselevel='final', serial=0)
  version_string: 3.9.2 (default, Feb 28 2021, 17:03:44)  [GCC 10.2.1 20210110]

***cpu_info***
  cpu_count: 2
  bits: 64bit
  processor: x86_64
  cpu_desc: AMD GX-212JC SOC with Radeon(TM) R2E Graphics
  serial_number: 
  hardware_desc: 
  model: 
  total_memory: 3439328
  memory_units: kB

***sd_info***

***distribution***
  name: Debian GNU/Linux 11 (bullseye)
  id: debian
  version: 11
  version_parts: {'major': '11', 'minor': '', 'build_number': ''}
  like: 
  codename: bullseye
  release_info: {}

***virtualization***
  virt_type: none
  virt_identifier: none

***network***

***canbus***

Systemd unit moonraker-TronXY.service:
unit_name: moonraker-TronXY.service
is_default: False
Properties:
**Requires=['system.slice', 'home-sashi.mount', 'network-online.target', '-.mount', 'sysinit.target']
**After=['systemd-journald.socket', '-.mount', 'basic.target', 'sysinit.target', 'home-sashi.mount', 'system.slice', 'network-online.target']
**SupplementaryGroups=['moonraker-admin']
**EnvironmentFiles=/home/sashi/TronXY_data/systemd/moonraker.env
**ExecStart=/home/sashi/moonraker-env/bin/python $MOONRAKER_ARGS
**WorkingDirectory=/home/sashi/moonraker
**FragmentPath=/etc/systemd/system/moonraker-TronXY.service
**Description=API Server for Klipper SV1 TronXY
**User=sashi

Systemd unit klipper-TronXY.service:
unit_name: klipper-TronXY.service
is_default: False
Properties:
**Description=Klipper 3D Printer Firmware SV1
**ExecStart=/home/sashi/klippy-env/bin/python $KLIPPER_ARGS
**FragmentPath=/etc/systemd/system/klipper-TronXY.service
Klipper Version: v0.11.0-40-gaac613bf
2022-12-22 02:42:00,249 [machine.py:_find_public_ip()] - Detected Local IP: 192.168.6.5
2022-12-22 02:42:10,265 [machine.py:_find_public_ip()] - Detected Local IP: 192.168.6.5
2022-12-22 12:17:12,902 [machine.py:_find_public_ip()] - Detected Local IP: 192.168.6.5
2022-12-22 12:17:22,924 [machine.py:_find_public_ip()] - Detected Local IP: 192.168.6.5
2022-12-22 12:48:56,233 [machine.py:_find_public_ip()] - Detected Local IP: 192.168.6.5
2022-12-22 12:49:06,247 [machine.py:_find_public_ip()] - Detected Local IP: 192.168.6.5
2022-12-22 13:23:49,826 [machine.py:_find_public_ip()] - Detected Local IP: 192.168.6.5
2022-12-22 13:24:09,850 [machine.py:_find_public_ip()] - Detected Local IP: 192.168.6.5
2022-12-22 14:02:23,992 [machine.py:_find_public_ip()] - Detected Local IP: 192.168.6.5
2022-12-22 14:02:34,006 [machine.py:_find_public_ip()] - Detected Local IP: 192.168.6.5
2022-12-22 15:00:50,079 [machine.py:_find_public_ip()] - Detected Local IP: 192.168.6.5
2022-12-22 15:01:50,210 [machine.py:_find_public_ip()] - Detected Local IP: 192.168.6.5
2022-12-22 15:25:22,749 [machine.py:_find_public_ip()] - Detected Local IP: 192.168.6.5
2022-12-22 15:25:32,769 [machine.py:_find_public_ip()] - Detected Local IP: 192.168.6.5
2022-12-22 15:32:13,453 [machine.py:_find_public_ip()] - Detected Local IP: 192.168.6.5
2022-12-22 15:32:23,473 [machine.py:_find_public_ip()] - Detected Local IP: 192.168.6.5
2022-12-22 15:46:24,874 [machine.py:_find_public_ip()] - Detected Local IP: 192.168.6.5
2022-12-22 15:46:34,889 [machine.py:_find_public_ip()] - Detected Local IP: 192.168.6.5
2022-12-22 16:37:00,105 [machine.py:_find_public_ip()] - Detected Local IP: 192.168.6.5
2022-12-22 16:37:10,124 [machine.py:_find_public_ip()] - Detected Local IP: 192.168.6.5
2022-12-22 16:43:10,722 [machine.py:_find_public_ip()] - Detected Local IP: 192.168.6.5
2022-12-22 16:43:20,737 [machine.py:_find_public_ip()] - Detected Local IP: 192.168.6.5
2022-12-22 16:55:11,939 [machine.py:_find_public_ip()] - Detected Local IP: 192.168.6.5
2022-12-22 16:55:21,960 [machine.py:_find_public_ip()] - Detected Local IP: 192.168.6.5
2022-12-22 17:28:40,211 [ioloop.py:_run_callback()] - Exception in callback functools.partial(<function _HTTPConnection.__init__.<locals>.<lambda> at 0x7f6b4eb72b80>, <Task finished name='Task-274219' coro=<_HTTPConnection.run() done, defined at /home/sashi/moonraker-env/lib/python3.9/site-packages/tornado/simple_httpclient.py:290> exception=gaierror(-3, 'Temporary failure in name resolution')>)
Traceback (most recent call last):
  File "/home/sashi/moonraker-env/lib/python3.9/site-packages/tornado/ioloop.py", line 740, in _run_callback
    ret = callback()
  File "/home/sashi/moonraker-env/lib/python3.9/site-packages/tornado/simple_httpclient.py", line 287, in <lambda>
    gen.convert_yielded(self.run()), lambda f: f.result()
  File "/home/sashi/moonraker-env/lib/python3.9/site-packages/tornado/simple_httpclient.py", line 340, in run
    stream = await self.tcp_client.connect(
  File "/home/sashi/moonraker-env/lib/python3.9/site-packages/tornado/tcpclient.py", line 265, in connect
    addrinfo = await self.resolver.resolve(host, port, af)
  File "/home/sashi/moonraker-env/lib/python3.9/site-packages/tornado/netutil.py", line 433, in resolve
    for fam, _, _, _, address in await asyncio.get_running_loop().getaddrinfo(
  File "/usr/lib/python3.9/asyncio/base_events.py", line 856, in getaddrinfo
    return await self.run_in_executor(
  File "/usr/lib/python3.9/concurrent/futures/thread.py", line 52, in run
    result = self.fn(*self.args, **self.kwargs)
  File "/usr/lib/python3.9/socket.py", line 953, in getaddrinfo
    for res in _socket.getaddrinfo(host, port, family, type, proto, flags):
socket.gaierror: [Errno -3] Temporary failure in name resolution
2022-12-22 17:36:36,354 [machine.py:_find_public_ip()] - Detected Local IP: 192.168.6.5
2022-12-22 17:36:46,378 [machine.py:_find_public_ip()] - Detected Local IP: 192.168.6.5
2022-12-22 18:28:25,058 [ioloop.py:_run_callback()] - Exception in callback functools.partial(<function _HTTPConnection.__init__.<locals>.<lambda> at 0x7f6b4d186d30>, <Task finished name='Task-286061' coro=<_HTTPConnection.run() done, defined at /home/sashi/moonraker-env/lib/python3.9/site-packages/tornado/simple_httpclient.py:290> exception=gaierror(-3, 'Temporary failure in name resolution')>)
Traceback (most recent call last):
  File "/home/sashi/moonraker-env/lib/python3.9/site-packages/tornado/ioloop.py", line 740, in _run_callback
    ret = callback()
  File "/home/sashi/moonraker-env/lib/python3.9/site-packages/tornado/simple_httpclient.py", line 287, in <lambda>
    gen.convert_yielded(self.run()), lambda f: f.result()
  File "/home/sashi/moonraker-env/lib/python3.9/site-packages/tornado/simple_httpclient.py", line 340, in run
    stream = await self.tcp_client.connect(
  File "/home/sashi/moonraker-env/lib/python3.9/site-packages/tornado/tcpclient.py", line 265, in connect
    addrinfo = await self.resolver.resolve(host, port, af)
  File "/home/sashi/moonraker-env/lib/python3.9/site-packages/tornado/netutil.py", line 433, in resolve
    for fam, _, _, _, address in await asyncio.get_running_loop().getaddrinfo(
  File "/usr/lib/python3.9/asyncio/base_events.py", line 856, in getaddrinfo
    return await self.run_in_executor(
  File "/usr/lib/python3.9/concurrent/futures/thread.py", line 52, in run
    result = self.fn(*self.args, **self.kwargs)
  File "/usr/lib/python3.9/socket.py", line 953, in getaddrinfo
    for res in _socket.getaddrinfo(host, port, family, type, proto, flags):
socket.gaierror: [Errno -3] Temporary failure in name resolution
2022-12-22 18:32:42,424 [machine.py:_find_public_ip()] - Detected Local IP: 192.168.6.5
2022-12-22 18:32:52,436 [machine.py:_find_public_ip()] - Detected Local IP: 192.168.6.5
2022-12-22 18:37:43,013 [machine.py:_find_public_ip()] - Detected Local IP: 192.168.6.5
2022-12-22 18:37:53,024 [machine.py:_find_public_ip()] - Detected Local IP: 192.168.6.5
2022-12-22 18:40:23,266 [machine.py:_find_public_ip()] - Detected Local IP: 192.168.6.5
2022-12-22 18:40:43,299 [machine.py:_find_public_ip()] - Detected Local IP: 192.168.6.5
2022-12-22 18:42:13,470 [machine.py:_find_public_ip()] - Detected Local IP: 192.168.6.5
2022-12-22 18:43:23,584 [machine.py:_find_public_ip()] - Detected Local IP: 192.168.6.5
2022-12-22 18:48:34,143 [machine.py:_find_public_ip()] - Detected Local IP: 192.168.6.5
2022-12-22 18:48:44,159 [machine.py:_find_public_ip()] - Detected Local IP: 192.168.6.5
2022-12-22 18:52:54,618 [machine.py:_find_public_ip()] - Detected Local IP: 192.168.6.5
2022-12-22 18:53:04,628 [machine.py:_find_public_ip()] - Detected Local IP: 192.168.6.5
2022-12-22 18:55:34,859 [machine.py:_find_public_ip()] - Detected Local IP: 192.168.6.5
2022-12-22 18:56:04,946 [machine.py:_find_public_ip()] - Detected Local IP: 192.168.6.5
2022-12-22 18:57:05,041 [machine.py:_find_public_ip()] - Detected Local IP: 192.168.6.5
2022-12-22 18:57:45,102 [machine.py:_find_public_ip()] - Detected Local IP: 192.168.6.5
2022-12-22 18:58:25,057 [ioloop.py:_run_callback()] - Exception in callback functools.partial(<function _HTTPConnection.__init__.<locals>.<lambda> at 0x7f6b4d1869d0>, <Task finished name='Task-292024' coro=<_HTTPConnection.run() done, defined at /home/sashi/moonraker-env/lib/python3.9/site-packages/tornado/simple_httpclient.py:290> exception=gaierror(-3, 'Temporary failure in name resolution')>)
Traceback (most recent call last):
  File "/home/sashi/moonraker-env/lib/python3.9/site-packages/tornado/ioloop.py", line 740, in _run_callback
    ret = callback()
  File "/home/sashi/moonraker-env/lib/python3.9/site-packages/tornado/simple_httpclient.py", line 287, in <lambda>
    gen.convert_yielded(self.run()), lambda f: f.result()
  File "/home/sashi/moonraker-env/lib/python3.9/site-packages/tornado/simple_httpclient.py", line 340, in run
    stream = await self.tcp_client.connect(
  File "/home/sashi/moonraker-env/lib/python3.9/site-packages/tornado/tcpclient.py", line 265, in connect
    addrinfo = await self.resolver.resolve(host, port, af)
  File "/home/sashi/moonraker-env/lib/python3.9/site-packages/tornado/netutil.py", line 433, in resolve
    for fam, _, _, _, address in await asyncio.get_running_loop().getaddrinfo(
  File "/usr/lib/python3.9/asyncio/base_events.py", line 856, in getaddrinfo
    return await self.run_in_executor(
  File "/usr/lib/python3.9/concurrent/futures/thread.py", line 52, in run
    result = self.fn(*self.args, **self.kwargs)
  File "/usr/lib/python3.9/socket.py", line 953, in getaddrinfo
    for res in _socket.getaddrinfo(host, port, family, type, proto, flags):
socket.gaierror: [Errno -3] Temporary failure in name resolution
2022-12-22 19:16:37,008 [machine.py:_find_public_ip()] - Detected Local IP: 192.168.6.5
2022-12-22 19:16:47,021 [machine.py:_find_public_ip()] - Detected Local IP: 192.168.6.5
2022-12-22 19:18:17,169 [machine.py:_find_public_ip()] - Detected Local IP: 192.168.6.5
2022-12-22 19:18:47,235 [machine.py:_find_public_ip()] - Detected Local IP: 192.168.6.5
2022-12-22 19:59:31,403 [machine.py:_find_public_ip()] - Detected Local IP: 192.168.6.5
2022-12-22 19:59:41,416 [machine.py:_find_public_ip()] - Detected Local IP: 192.168.6.5
2022-12-22 20:12:22,720 [machine.py:_find_public_ip()] - Detected Local IP: 192.168.6.5
2022-12-22 20:12:32,734 [machine.py:_find_public_ip()] - Detected Local IP: 192.168.6.5
2022-12-22 20:14:42,981 [machine.py:_find_public_ip()] - Detected Local IP: 192.168.6.5
2022-12-22 20:14:52,999 [machine.py:_find_public_ip()] - Detected Local IP: 192.168.6.5
2022-12-22 20:28:25,056 [ioloop.py:_run_callback()] - Exception in callback functools.partial(<function _HTTPConnection.__init__.<locals>.<lambda> at 0x7f6b4eb72b80>, <Task finished name='Task-309865' coro=<_HTTPConnection.run() done, defined at /home/sashi/moonraker-env/lib/python3.9/site-packages/tornado/simple_httpclient.py:290> exception=gaierror(-3, 'Temporary failure in name resolution')>)
Traceback (most recent call last):
  File "/home/sashi/moonraker-env/lib/python3.9/site-packages/tornado/ioloop.py", line 740, in _run_callback
    ret = callback()
  File "/home/sashi/moonraker-env/lib/python3.9/site-packages/tornado/simple_httpclient.py", line 287, in <lambda>
    gen.convert_yielded(self.run()), lambda f: f.result()
  File "/home/sashi/moonraker-env/lib/python3.9/site-packages/tornado/simple_httpclient.py", line 340, in run
    stream = await self.tcp_client.connect(
  File "/home/sashi/moonraker-env/lib/python3.9/site-packages/tornado/tcpclient.py", line 265, in connect
    addrinfo = await self.resolver.resolve(host, port, af)
  File "/home/sashi/moonraker-env/lib/python3.9/site-packages/tornado/netutil.py", line 433, in resolve
    for fam, _, _, _, address in await asyncio.get_running_loop().getaddrinfo(
  File "/usr/lib/python3.9/asyncio/base_events.py", line 856, in getaddrinfo
    return await self.run_in_executor(
  File "/usr/lib/python3.9/concurrent/futures/thread.py", line 52, in run
    result = self.fn(*self.args, **self.kwargs)
  File "/usr/lib/python3.9/socket.py", line 953, in getaddrinfo
    for res in _socket.getaddrinfo(host, port, family, type, proto, flags):
socket.gaierror: [Errno -3] Temporary failure in name resolution
2022-12-22 21:46:12,903 [machine.py:_find_public_ip()] - Detected Local IP: 192.168.6.5
2022-12-22 21:46:22,951 [machine.py:_find_public_ip()] - Detected Local IP: 192.168.6.5
2022-12-22 22:23:46,848 [machine.py:_find_public_ip()] - Detected Local IP: 192.168.6.5
2022-12-22 22:23:56,866 [machine.py:_find_public_ip()] - Detected Local IP: 192.168.6.5
2022-12-22 22:24:36,958 [machine.py:_find_public_ip()] - Detected Local IP: 192.168.6.5
2022-12-22 22:25:57,080 [machine.py:_find_public_ip()] - Detected Local IP: 192.168.6.5
2022-12-22 22:32:47,803 [machine.py:_find_public_ip()] - Detected Local IP: 192.168.6.5
2022-12-22 22:33:27,871 [machine.py:_find_public_ip()] - Detected Local IP: 192.168.6.5
2022-12-22 22:36:48,248 [machine.py:_find_public_ip()] - Detected Local IP: 192.168.6.5
2022-12-22 22:37:08,276 [machine.py:_find_public_ip()] - Detected Local IP: 192.168.6.5
2022-12-22 22:38:48,420 [machine.py:_find_public_ip()] - Detected Local IP: 192.168.6.5
2022-12-22 22:39:28,480 [machine.py:_find_public_ip()] - Detected Local IP: 192.168.6.5
2022-12-22 22:43:48,928 [machine.py:_find_public_ip()] - Detected Local IP: 192.168.6.5
2022-12-22 22:44:18,970 [machine.py:_find_public_ip()] - Detected Local IP: 192.168.6.5
2022-12-22 23:00:10,609 [machine.py:_find_public_ip()] - Detected Local IP: 192.168.6.5
2022-12-22 23:00:20,622 [machine.py:_find_public_ip()] - Detected Local IP: 192.168.6.5
2022-12-22 23:13:11,939 [machine.py:_find_public_ip()] - Detected Local IP: 192.168.6.5
2022-12-22 23:13:21,969 [machine.py:_find_public_ip()] - Detected Local IP: 192.168.6.5
2022-12-22 23:45:35,358 [machine.py:_find_public_ip()] - Detected Local IP: 192.168.6.5
2022-12-22 23:45:45,374 [machine.py:_find_public_ip()] - Detected Local IP: 192.168.6.5
2022-12-22 23:52:06,043 [machine.py:_find_public_ip()] - Detected Local IP: 192.168.6.5
2022-12-22 23:52:16,061 [machine.py:_find_public_ip()] - Detected Local IP: 192.168.6.5
